Workbook

Sheet README
A1: Nabd — Hospital / Clinic Management System
A2: Implementation Task Plan v2 — rebuilt against the updated wireframe
A4: Prepared for | B4: Harish
A5: Date | B5: 13 August 2026
A6: Supersedes | B6: v1 of 11 August 2026 (202 tasks, 1,210 points)
A7: Source | B7: Nabd wireframe (Platform Console v29 + current shell) and DESIGN.md in the connected folder
A9: WHAT THE UPDATED WIREFRAME CHANGED
A10: The wireframe now carries a formal requirement register — 185 identifiers across 30 prefixes (SYS, PAT, CGV, CAD, RCP, OWN, PKG, BIL,
A11: PHR, CMP, DPO, SSA, SCS, AGG, CEO, NFR, MKT and nine clinical specialties). Every task below is traced to those identifiers, and the
A12: Requirement Coverage tab proves all 185 are covered.
A13: Four product areas exist now that did not exist in v1: the patient WhatsApp surface, caregiver and family handling, the aggregator layer,
A14: and a rebuilt platform console with seven distinct SaaS operator roles.
A15: DESIGN.md gained a full chart system (sections 8.22-8.29) and a messaging component set (8.16-8.21). Both are now build epics.
A16: Scope roughly doubled: 349 tasks and 2,260 points against v1's 202 and 1,210.
A18: EXPLICIT NON-GOALS TAKEN FROM THE WIREFRAME — do not build these
A19: NFR-06 | B19: No SSO and no hardware security keys. Staff sign in with WhatsApp OTP, a short PIN or an authenticator app. The v1 SSO/OIDC task has been deleted.
A20: CAD-10 | B20: No payroll engine. Payroll is a CSV export only.
A21: SYS-10 | B21: No live claims pipeline. Full claims go via certified middleware in Phase 3. Ayushman is out of scope. Only a simple claim export (BIL-11) and NPHIES eligibility-check-lite (RCP-07) are in scope.
A22: PHR-04 | B22: Controlled drugs get a warning and a register entry, never a hard block — no registered pharmacist licence is assumed.
A23: CEO-14 | B23: No review filtering or gating. Nabd and Google ratings are never blended into one number.
A24: CEO-25 | B24: Adherence data is capture-only and is never monetised.
A25: AGG-03 | B25: Word-to-specialty matching only. No symptom interpretation and no clinical triage.
A26: PED-04 | B26: Growth percentiles are never calculated in the UI — only a validated growth service may produce them.
A28: PLANNING ASSUMPTIONS — edit the blue cells; everything derived recalculates
A29: Assumption | B29: Value | C29: Note
A30: Sprint length (weeks) | B30: 2 | C30: Standard two-week iteration
A31: Velocity per squad (points / sprint) | B31: 40 | C31: A squad is roughly 6 people. Sprint capacity = this multiplied by the squads active that sprint.
A32: Person-days per story point | B32: 0.6 | C32: Calibrate after two or three sprints; drives the indicative effort column only.
A33: Blended cost per person-day | B33: 0 | C33: Optional — enter your rate to cost the plan. Left at zero by the author.
A34: Peak squads in parallel | B34: 5 | C34: Reached in sprints 14-18. Roughly 30 delivery people at peak — this scope cannot be absorbed by one team.
A37: TABS
A38: Tab | B38: Purpose
A39: Backlog | B39: The full task list — 349 rows. One row is one epic-level story. Edit Status, Sprint, Points and Owner.
A40: Requirement Coverage | B40: Every one of the 185 wireframe requirement identifiers mapped to the tasks that deliver it. Zero uncovered is the release gate.
A41: Epics | B41: Automatic rollup by epic. All formulas — do not type here.
A42: Sprints | B42: Sprint load against ramped squad capacity. Over-capacity sprints turn red.
A43: Tracks | B43: Rollup by parallel delivery track, showing how the four tracks are staffed.
A44: RBAC Matrix | B44: The clinic role and permission grid taken from the wireframe — the specification for epic E06.
A45: SaaS Operator Roles | B45: The seven platform-side roles from SSA-02 and what each may reach.
A46: Security Controls | B46: Cybersecurity, privacy and compliance controls mapped to delivering tasks, with a go-live gate counter.
...

Sheet Backlog
A1: ID | B1: Epic | C1: Module | D1: Task | E1: Description | F1: Requirement IDs | G1: Roles Impacted | H1: Track | I1: Discipline | J1: Priority | K1: Delivery Phase | L1: Story Points | M1: Sprint | N1: Release Band | O1: Est. Person-Days | P1: Depends On | Q1: Acceptance Criteria | R1: Status | S1: Owner / Squad
A2: NB-001 | B2: E01 Foundation & Architecture | C2: Architecture | D2: Define target architecture & ADR set | E2: Modular monolith + Postgres, region-isolated stacks for India and KSA, event bus for messaging. ADRs for datastore, tenancy, hosting. | F2: SYS-14,NFR-04 | G2: All | H2: Shared | I2: Architecture | J2: Must | K2: MVP | L2: 8 | M2: 1 | N2: =IF(M2<=4,"R1 Foundation",IF(M2<=8,"R2 Core Clinic",IF(M2<=13,"R3 Revenue & Messaging",IF(M2<=18,"R4 Patient & Platform",IF(M2<=20,"R5 Harden","R6 Launch"))))) | O2: =L2*README!$B$32 | Q2: ADRs approved; C4 L1/L2 published; region topology signed off | R2: Not started
A3: NB-002 | B3: E01 Foundation & Architecture | C3: Architecture | D3: Multi-tenancy isolation model + irreversible region lock | E3: Region is chosen at provisioning and locked permanently. No cross-region replication; region-scoped KMS keys. | F3: SYS-14,NFR-04 | G3: Platform | H3: Shared | I3: Architecture | J3: Must | K3: MVP | L3: 8 | M3: 1 | N3: =IF(M3<=4,"R1 Foundation",IF(M3<=8,"R2 Core Clinic",IF(M3<=13,"R3 Revenue & Messaging",IF(M3<=18,"R4 Patient & Platform",IF(M3<=20,"R5 Harden","R6 Launch"))))) | O3: =L3*README!$B$32 | P3: NB-001 | Q3: PoC proves row-level isolation; region field immutable after provisioning; attempt to change is rejected and audited | R3: Not started
A4: NB-003 | B4: E01 Foundation & Architecture | C4: Data | D4: Core data model & ERD | E4: Tenant, Clinic, Branch, Staff, Role, Patient, FamilyMember, Encounter, Appointment, Invoice, Package, Prescription, PharmacyItem, ConsentRecord, AuditEvent. | F4: SYS-13 | G4: All | H4: Shared | I4: Backend | J4: Must | K4: MVP | L4: 13 | M4: 1 | N4: =IF(M4<=4,"R1 Foundation",IF(M4<=8,"R2 Core Clinic",IF(M4<=13,"R3 Revenue & Messaging",IF(M4<=18,"R4 Patient & Platform",IF(M4<=20,"R5 Harden","R6 Launch"))))) | O4: =L4*README!$B$32 | P4: NB-001 | Q4: ERD reviewed; migrations generated; naming conventions documented | R4: Not started
A5: NB-004 | B5: E01 Foundation & Architecture | C5: Data | D5: Database migration framework & seed data | E5: Versioned reversible migrations; seed tenants for India and KSA demo clinics matching the wireframe fixtures. | G5: All | H5: Shared | I5: Backend | J5: Must | K5: MVP | L5: 3 | M5: 2 | N5: =IF(M5<=4,"R1 Foundation",IF(M5<=8,"R2 Core Clinic",IF(M5<=13,"R3 Revenue & Messaging",IF(M5<=18,"R4 Patient & Platform",IF(M5<=20,"R5 Harden","R6 Launch"))))) | O5: =L5*README!$B$32 | P5: NB-003 | Q5: Migrate up/down clean; seeds reproduce wireframe demo data | R5: Not started
A6: NB-005 | B6: E01 Foundation & Architecture | C6: API | D6: API standards, versioning & error contract | E6: REST /v1, RFC7807 errors, pagination, idempotency keys on every financial and clinical write. | F6: SYS-06 | G6: All | H6: Shared | I6: Backend | J6: Must | K6: MVP | L6: 5 | M6: 2 | N6: =IF(M6<=4,"R1 Foundation",IF(M6<=8,"R2 Core Clinic",IF(M6<=13,"R3 Revenue & Messaging",IF(M6<=18,"R4 Patient & Platform",IF(M6<=20,"R5 Harden","R6 Launch"))))) | O6: =L6*README!$B$32 | P6: NB-001 | Q6: OpenAPI published; CI linter enforces the standard | R6: Not started
A7: NB-006 | B7: E01 Foundation & Architecture | C7: API | D7: API gateway & per-role BFF layer | E7: Single entry point; role-shaped payloads so the mobile queue screen stays small. | F7: NFR-02 | G7: All | H7: Shared | I7: Backend | J7: Should | K7: MVP | L7: 5 | M7: 3 | N7: =IF(M7<=4,"R1 Foundation",IF(M7<=8,"R2 Core Clinic",IF(M7<=13,"R3 Revenue & Messaging",IF(M7<=18,"R4 Patient & Platform",IF(M7<=20,"R5 Harden","R6 Launch"))))) | O7: =L7*README!$B$32 | P7: NB-005 | Q7: p95 payload under 150KB on the queue screen | R7: Not started
A8: NB-007 | B8: E01 Foundation & Architecture | C8: Platform | D8: Event bus & transactional outbox | E8: No clinical, billing or messaging event may be lost. Drives WhatsApp, SMS, recall and webhooks. | F8: SYS-01,NFR-12 | G8: All | H8: Shared | I8: Backend | J8: Must | K8: MVP | L8: 8 | M8: 3 | N8: =IF(M8<=4,"R1 Foundation",IF(M8<=8,"R2 Core Clinic",IF(M8<=13,"R3 Revenue & Messaging",IF(M8<=18,"R4 Patient & Platform",IF(M8<=20,"R5 Harden","R6 Launch"))))) | O8: =L8*README!$B$32 | P8: NB-003, NB-005 | Q8: Zero message loss under forced consumer failure | R8: Not started
A9: NB-008 | B9: E01 Foundation & Architecture | C9: Platform | D9: Feature-flag & module-entitlement service | E9: Drives Included / Trial / Paid add-on / Upgrade required / Disabled-by-clinic / Disabled-by-platform states. | F9: SYS-20,CAD-13 | G9: Owner,Platform | H9: Shared | I9: Backend | J9: Must | K9: MVP | L9: 8 | M9: 3 | N9: =IF(M9<=4,"R1 Foundation",IF(M9<=8,"R2 Core Clinic",IF(M9<=13,"R3 Revenue & Messaging",IF(M9<=18,"R4 Patient & Platform",IF(M9<=20,"R5 Harden","R6 Launch"))))) | O9: =L9*README!$B$32 | P9: NB-001, NB-002 | Q9: Entitlement change propagates in under 60s; upgrade/downgrade under 5 minutes with no data loss | R9: Not started
A10: NB-009 | B10: E01 Foundation & Architecture | C10: Platform | D10: Config & secrets management with role separation | E10: Installation secrets are separate from tenant integration secrets — two different operator roles. | F10: SYS-14 | G10: All | H10: Shared | I10: DevOps | J10: Must | K10: MVP | L10: 5 | M10: 2 | N10: =IF(M10<=4,"R1 Foundation",IF(M10<=8,"R2 Core Clinic",IF(M10<=13,"R3 Revenue & Messaging",IF(M10<=18,"R4 Patient & Platform",IF(M10<=20,"R5 Harden","R6 Launch"))))) | O10: =L10*README!$B$32 | P10: NB-299 | Q10: Secret scan clean; installation and tenant secrets held in separate scopes with separate access | R10: Not started
A11: NB-010 | B11: E01 Foundation & Architecture | C11: Data | D11: Reference data service | E11: ICD-10 subset, drug master (India NMC generics + KSA SFDA identifiers), charge catalogue, GST/VAT rate tables, vaccine schedules. | F11: GP-05,DOC-06 | G11: Doctor,Reception | H11: Shared | I11: Backend | J11: Must | K11: MVP | L11: 8 | M11: 4 | N11: =IF(M11<=4,"R1 Foundation",IF(M11<=8,"R2 Core Clinic",IF(M11<=13,"R3 Revenue & Messaging",IF(M11<=18,"R4 Patient & Platform",IF(M11<=20,"R5 Harden","R6 Launch"))))) | O11: =L11*README!$B$32 | P11: NB-003 | Q11: Catalogue seeded; rates and drug lists versioned by effective date | R11: Not started
A12: NB-011 | B12: E01 Foundation & Architecture | C12: Platform | D12: Shared reason-code service | E12: One shared reason list reused by cancellation, reschedule, block, override and refusal flows. | F12: SYS-07 | G12: All | H12: Shared | I12: Backend | J12: Must | K12: MVP | L12: 3 | M12: 4 | N12: =IF(M12<=4,"R1 Foundation",IF(M12<=8,"R2 Core Clinic",IF(M12<=13,"R3 Revenue & Messaging",IF(M12<=18,"R4 Patient & Platform",IF(M12<=20,"R5 Harden","R6 Launch"))))) | O12: =L12*README!$B$32 | P12: NB-003 | Q12: Every reason-capture surface reads from this service; reasons are configurable per tenant | R12: Not started
A13: NB-012 | B13: E02 Design System & UI Kit | C13: Design System | D13: Tokenise DESIGN.md into a theme package | E13: All --nb-* colour, spacing, radius, elevation and motion tokens as a shared package. | G13: All | H13: Shared | I13: Frontend | J13: Must | K13: MVP | L13: 5 | M13: 1 | N13: =IF(M13<=4,"R1 Foundation",IF(M13<=8,"R2 Core Clinic",IF(M13<=13,"R3 Revenue & Messaging",IF(M13<=18,"R4 Patient & Platform",IF(M13<=20,"R5 Harden","R6 Launch"))))) | O13: =L13*README!$B$32 | Q13: Token package published; visual diff vs wireframe under 2px | R13: Not started
A14: NB-013 | B14: E02 Design System & UI Kit | C14: Design System | D14: Core controls — button, input, select, segmented, chip | E14: Per DESIGN.md 8.1-8.4 with every rest/hover/active/focus/disabled/loading state. | G14: All | H14: Shared | I14: Frontend | J14: Must | K14: MVP | L14: 8 | M14: 2 | N14: =IF(M14<=4,"R1 Foundation",IF(M14<=8,"R2 Core Clinic",IF(M14<=13,"R3 Revenue & Messaging",IF(M14<=18,"R4 Patient & Platform",IF(M14<=20,"R5 Harden","R6 Launch"))))) | O14: =L14*README!$B$32 | P14: NB-012 | Q14: Storybook covers every state; a11y checks pass | R14: Not started
A15: NB-014 | B15: E02 Design System & UI Kit | C15: Design System | D15: Containers — card, table, mobile list row, drawer, modal, bottom sheet | E15: Per 8.5-8.13 including the sub-768px table-to-card replacement. | G15: All | H15: Shared | I15: Frontend | J15: Must | K15: MVP | L15: 8 | M15: 2 | N15: =IF(M15<=4,"R1 Foundation",IF(M15<=8,"R2 Core Clinic",IF(M15<=13,"R3 Revenue & Messaging",IF(M15<=18,"R4 Patient & Platform",IF(M15<=20,"R5 Harden","R6 Launch"))))) | O15: =L15*README!$B$32 | P15: NB-012 | Q15: Responsive switch verified at 767/768px; focus trap correct | R15: Not started
A16: NB-015 | B16: E02 Design System & UI Kit | C16: Design System | D16: Clinical state system — pill, badge, critical shape cue | E16: Nine states, each hue + icon + text; critical adds a shape cue and a 3px left bar. | G16: All | H16: Shared | I16: Frontend | J16: Must | K16: MVP | L16: 5 | M16: 3 | N16: =IF(M16<=4,"R1 Foundation",IF(M16<=8,"R2 Core Clinic",IF(M16<=13,"R3 Revenue & Messaging",IF(M16<=18,"R4 Patient & Platform",IF(M16<=20,"R5 Harden","R6 Launch"))))) | O16: =L16*README!$B$32 | P16: NB-012 | Q16: Colour-blind simulation review passed; no hue-only state anywhere | R16: Not started
A17: NB-016 | B17: E02 Design System & UI Kit | C17: Design System | D17: Icon sprite & illustration tier | E17: Single monoline family at stroke 1.75; 3D illustration set reserved for empty and success states only. | G17: All | H17: Shared | I17: Frontend | J17: Must | K17: MVP | L17: 3 | M17: 2 | N17: =IF(M17<=4,"R1 Foundation",IF(M17<=8,"R2 Core Clinic",IF(M17<=13,"R3 Revenue & Messaging",IF(M17<=18,"R4 Patient & Platform",IF(M17<=20,"R5 Harden","R6 Launch"))))) | O17: =L17*README!$B$32 | P17: NB-012 | Q17: Sprite built from the wireframe symbols; lint blocks a second UI icon family | R17: Not started
A18: NB-017 | B18: E02 Design System & UI Kit | C18: Design System | D18: App shell — sidebar, sectioned nav, rail, top bar, bottom nav | E18: 248px sidebar / 72px collapsed / 88px rail / 64px bottom nav, with section grouping for the platform console. | F18: SSA-02 | G18: All | H18: Shared | I18: Frontend | J18: Must | K18: MVP | L18: 8 | M18: 3 | N18: =IF(M18<=4,"R1 Foundation",IF(M18<=8,"R2 Core Clinic",IF(M18<=13,"R3 Revenue & Messaging",IF(M18<=18,"R4 Patient & Platform",IF(M18<=20,"R5 Harden","R6 Launch"))))) | O18: =L18*README!$B$32 | P18: NB-014, NB-013 | Q18: Shell renders at all four breakpoints; nav sections group correctly | R18: Not started
A19: NB-018 | B19: E02 Design System & UI Kit | C19: Design System | D19: Messaging component set | E19: Message bubble, template card with variable-only editing, interactive reply set, conversation row, delivery-state chip, session-window indicator (8.16-8.21). | F19: RCP-11,CMP-07 | G19: All | H19: Shared | I19: Frontend | J19: Must | K19: MVP | L19: 8 | M19: 6 | N19: =IF(M19<=4,"R1 Foundation",IF(M19<=8,"R2 Core Clinic",IF(M19<=13,"R3 Revenue & Messaging",IF(M19<=18,"R4 Patient & Platform",IF(M19<=20,"R5 Harden","R6 Launch"))))) | O19: =L19*README!$B$32 | P19: NB-013, NB-014 | Q19: Template card makes fixed text physically uneditable; session indicator gates the composer | R19: Not started
A20: NB-019 | B20: E02 Design System & UI Kit | C20: Design System | D20: Command palette (Cmd/Ctrl-K) | E20: Grouped, role-scoped results. Platform console searches clinics, tickets, invoices and provisioning jobs. | G20: All | H20: Shared | I20: Frontend | J20: Should | K20: MVP | L20: 5 | M20: 8 | N20: =IF(M20<=4,"R1 Foundation",IF(M20<=8,"R2 Core Clinic",IF(M20<=13,"R3 Revenue & Messaging",IF(M20<=18,"R4 Patient & Platform",IF(M20<=20,"R5 Harden","R6 Launch"))))) | O20: =L20*README!$B$32 | P20: NB-017 | Q20: Only permitted entities appear for the signed-in role | R20: Not started
A21: NB-020 | B21: E02 Design System & UI Kit | C21: Design System | D21: Loading, empty, error, offline & permission state patterns | E21: Skeleton shimmer, 140px illustration empties, inline errors, sync banner, absent-not-disabled permission handling. | F21: NFR-12 | G21: All | H21: Shared | I21: Frontend | J21: Must | K21: MVP | L21: 5 | M21: 4 | N21: =IF(M21<=4,"R1 Foundation",IF(M21<=8,"R2 Core Clinic",IF(M21<=13,"R3 Revenue & Messaging",IF(M21<=18,"R4 Patient & Platform",IF(M21<=20,"R5 Harden","R6 Launch"))))) | O21: =L21*README!$B$32 | P21: NB-014 | Q21: Every list screen implements all states; no disabled element carries a permission reason | R21: Not started
A22: NB-021 | B22: E02 Design System & UI Kit | C22: Design System | D22: Light theme build | E22: DESIGN.md 1.7 mapping. Blocked on stakeholder approval — still marked NEEDS APPROVAL in the source. | G22: All | H22: Shared | I22: Frontend | J22: Could | K22: Phase 2 | L22: 5 | M22: 19 | N22: =IF(M22<=4,"R1 Foundation",IF(M22<=8,"R2 Core Clinic",IF(M22<=13,"R3 Revenue & Messaging",IF(M22<=18,"R4 Patient & Platform",IF(M22<=20,"R5 Harden","R6 Launch"))))) | O22: =L22*README!$B$32 | P22: NB-012 | Q22: Light theme passes AA on all tokens; per-user toggle persists | R22: Not started
A23: NB-022 | B23: E03 Chart & Data-Visualisation System | C23: Charts | D23: Chart colour foundation & series palette | E23: Eight categorical series in the OKLCH 0.49-0.53 band, sequential and diverging ramps, neutral diverging midpoint. Reserved state colours never appear as a series. | F23: GP-03,PED-03 | G23: All | H23: Shared | I23: Frontend | J23: Must | K23: MVP | L23: 8 | M23: 5 | N23: =IF(M23<=4,"R1 Foundation",IF(M23<=8,"R2 Core Clinic",IF(M23<=13,"R3 Revenue & Messaging",IF(M23<=18,"R4 Patient & Platform",IF(M23<=20,"R5 Harden","R6 Launch"))))) | O23: =L23*README!$B$32 | P23: NB-012 | Q23: All eight series at 3:1 on surface-1; automated check rejects any state colour used as series identity | R23: Not started
A24: NB-023 | B24: E03 Chart & Data-Visualisation System | C24: Charts | D24: All-pairs gate & series-count guard | E24: Only slots 1-3 clear the all-pairs gate; slots 4 and 6 must never share an all-pairs chart. Past three series, fold to Other or facet. | F24: GP-03 | G24: All | H24: Shared | I24: Frontend | J24: Must | K24: MVP | L24: 5 | M24: 5 | N24: =IF(M24<=4,"R1 Foundation",IF(M24<=8,"R2 Core Clinic",IF(M24<=13,"R3 Revenue & Messaging",IF(M24<=18,"R4 Patient & Platform",IF(M24<=20,"R5 Harden","R6 Launch"))))) | O24: =L24*README!$B$32 | P24: NB-022 | Q24: Component refuses a fourth series in scatter/bubble/small-multiple mode and folds to Other | R24: Not started
A25: NB-024 | B25: E03 Chart & Data-Visualisation System | C25: Charts | D25: Column, bar, line & area primitives | E25: Inline SVG only, no charting library, no canvas. 24px max thickness, 2px surface gap, 2px line, markers with surface ring. | F25: NFR-02 | G25: All | H25: Shared | I25: Frontend | J25: Must | K25: MVP | L25: 8 | M25: 6 | N25: =IF(M25<=4,"R1 Foundation",IF(M25<=8,"R2 Core Clinic",IF(M25<=13,"R3 Revenue & Messaging",IF(M25<=18,"R4 Patient & Platform",IF(M25<=20,"R5 Harden","R6 Launch"))))) | O25: =L25*README!$B$32 | P25: NB-022 | Q25: No third-party chart library in the bundle; renders under budget on a mid-range Android | R25: Not started
A26: NB-025 | B26: E03 Chart & Data-Visualisation System | C26: Charts | D26: Stat tile, meter & sparkline | E26: Auto-compacted values (1,284 / 12.9K / Rs 4.2L), signed delta coloured by direction and whether up is good. | F26: OWN-01 | G26: Owner | H26: Shared | I26: Frontend | J26: Must | K26: MVP | L26: 5 | M26: 6 | N26: =IF(M26<=4,"R1 Foundation",IF(M26<=8,"R2 Core Clinic",IF(M26<=13,"R3 Revenue & Messaging",IF(M26<=18,"R4 Patient & Platform",IF(M26<=20,"R5 Harden","R6 Launch"))))) | O26: =L26*README!$B$32 | P26: NB-022 | Q26: Compaction correct for INR lakh and SAR conventions in all three languages | R26: Not started
A27: NB-026 | B27: E03 Chart & Data-Visualisation System | C27: Charts | D27: Legend, direct labels, tooltip & crosshair | E27: Reuses the 8.9 tooltip surface. Labels never wear the series colour; a label that will not fit moves or drops to the tooltip, never clips. | G27: All | H27: Shared | I27: Frontend | J27: Must | K27: MVP | L27: 5 | M27: 7 | N27: =IF(M27<=4,"R1 Foundation",IF(M27<=8,"R2 Core Clinic",IF(M27<=13,"R3 Revenue & Messaging",IF(M27<=18,"R4 Patient & Platform",IF(M27<=20,"R5 Harden","R6 Launch"))))) | O27: =L27*README!$B$32 | P27: NB-024 | Q27: No clipped label at any breakpoint; single-series charts render no legend | R27: Not started
A28: NB-027 | B28: E03 Chart & Data-Visualisation System | C28: Charts | D28: Mandatory table view & export path for every chart | E28: Every chart ships a table view — the sub-3:1 relief channel, the screen-reader equivalent and the export path. | F28: SYS-23 | G28: All | H28: Shared | I28: Frontend | J28: Must | K28: MVP | L28: 5 | M28: 7 | N28: =IF(M28<=4,"R1 Foundation",IF(M28<=8,"R2 Core Clinic",IF(M28<=13,"R3 Revenue & Messaging",IF(M28<=18,"R4 Patient & Platform",IF(M28<=20,"R5 Harden","R6 Launch"))))) | O28: =L28*README!$B$32 | P28: NB-024 | Q28: No chart ships without a table view; screen reader reads the table, not the SVG | R28: Not started
A29: NB-028 | B29: E03 Chart & Data-Visualisation System | C29: Charts | D29: Ten chart states | E29: Empty with reason, single data point, insufficient data, loading, offline/stale, partial data (gaps stay gaps), unit-ambiguous, threshold band, permission-restricted, subscription-unavailable. | F29: PED-03,GP-03 | G29: All | H29: Shared | I29: Frontend | J29: Must | K29: MVP | L29: 8 | M29: 8 | N29: =IF(M29<=4,"R1 Foundation",IF(M29<=8,"R2 Core Clinic",IF(M29<=13,"R3 Revenue & Messaging",IF(M29<=18,"R4 Patient & Platform",IF(M29<=20,"R5 Harden","R6 Launch"))))) | O29: =L29*README!$B$32 | P29: NB-024, NB-020 | Q29: All ten states demonstrated; a one-point trend degrades to a stat tile rather than erroring | R29: Not started
A30: NB-029 | B30: E03 Chart & Data-Visualisation System | C30: Charts | D30: Chart RTL & aggregation rules | E30: Time axes never mirror; category axes and legends do. Charts past ~200 marks aggregate before rendering and say so. | F30: NFR-02 | G30: All | H30: Shared | I30: Frontend | J30: Must | K30: MVP | L30: 5 | M30: 9 | N30: =IF(M30<=4,"R1 Foundation",IF(M30<=8,"R2 Core Clinic",IF(M30<=13,"R3 Revenue & Messaging",IF(M30<=18,"R4 Patient & Platform",IF(M30<=20,"R5 Harden","R6 Launch"))))) | O30: =L30*README!$B$32 | P30: NB-024, NB-031 | Q30: Arabic time-axis chart verified unmirrored; 500-mark dataset aggregates with a visible notice | R30: Not started
A31: NB-030 | B31: E04 Localisation, RTL & i18n | C31: i18n | D31: i18n framework & string extraction pipeline | E31: EN / AR / HI bundles plus the patient-side language set (Hinglish, Tamil, Malayalam, Kannada, Bengali). No hardcoded strings. | F31: PAT-15 | G31: All | H31: Shared | I31: Frontend | J31: Must | K31: MVP | L31: 8 | M31: 3 | N31: =IF(M31<=4,"R1 Foundation",IF(M31<=8,"R2 Core Clinic",IF(M31<=13,"R3 Revenue & Messaging",IF(M31<=18,"R4 Patient & Platform",IF(M31<=20,"R5 Harden","R6 Launch"))))) | O31: =L31*README!$B$32 | P31: NB-017 | Q31: Lint fails on literal UI strings; pseudo-locale build available | R31: Not started
A32: NB-031 | B32: E04 Localisation, RTL & i18n | C32: i18n | D32: RTL layout engine — logical properties only | E32: No left/right in shipped CSS. Nav, drawer, table order, chevrons and selected bar all mirror. | G32: All | H32: Shared | I32: Frontend | J32: Must | K32: MVP | L32: 8 | M32: 4 | N32: =IF(M32<=4,"R1 Foundation",IF(M32<=8,"R2 Core Clinic",IF(M32<=13,"R3 Revenue & Messaging",IF(M32<=18,"R4 Patient & Platform",IF(M32<=20,"R5 Harden","R6 Launch"))))) | O32: =L32*README!$B$32 | P32: NB-030, NB-017 | Q32: Stylelint blocks physical properties; RTL screenshot suite passes | R32: Not started
A33: NB-032 | B33: E04 Localisation, RTL & i18n | C33: i18n | D33: RTL non-mirroring exception list including anatomy | E33: Clock glyphs, media, pulse mark, all time axes, phone numbers, Latin IDs, illustrations — and anatomy: the dental arch and dermatology body map keep fixed LTR order with both ends labelled. | F33: DENT-01,DERM-04 | G33: All | H33: Shared | I33: Frontend | J33: Must | K33: MVP | L33: 5 | M33: 5 | N33: =IF(M33<=4,"R1 Foundation",IF(M33<=8,"R2 Core Clinic",IF(M33<=13,"R3 Revenue & Messaging",IF(M33<=18,"R4 Patient & Platform",IF(M33<=20,"R5 Harden","R6 Launch"))))) | O33: =L33*README!$B$32 | P33: NB-031 | Q33: Dental arch and body map verified unmirrored in Arabic with explicit end labels | R33: Not started
A34: NB-033 | B34: E04 Localisation, RTL & i18n | C34: i18n | D34: Arabic & Devanagari typography | E34: IBM Plex Sans Arabic pairing, line-height +0.1em, letter-spacing forced to zero. | G34: All | H34: Shared | I34: Frontend | J34: Must | K34: MVP | L34: 3 | M34: 4 | N34: =IF(M34<=4,"R1 Foundation",IF(M34<=8,"R2 Core Clinic",IF(M34<=13,"R3 Revenue & Messaging",IF(M34<=18,"R4 Patient & Platform",IF(M34<=20,"R5 Harden","R6 Launch"))))) | O34: =L34*README!$B$32 | P34: NB-030 | Q34: Arabic renders untracked; no clipped descenders | R34: Not started
A35: NB-034 | B35: E04 Localisation, RTL & i18n | C35: i18n | D35: Hijri + Gregorian dual calendar | E35: KSA tenants show Hijri primary with Gregorian secondary on one line; India Gregorian only. | G35: Reception,Doctor,Owner | H35: Shared | I35: Frontend | J35: Must | K35: MVP | L35: 5 | M35: 5 | N35: =IF(M35<=4,"R1 Foundation",IF(M35<=8,"R2 Core Clinic",IF(M35<=13,"R3 Revenue & Messaging",IF(M35<=18,"R4 Patient & Platform",IF(M35<=20,"R5 Harden","R6 Launch"))))) | O35: =L35*README!$B$32 | P35: NB-030 | Q35: Date component unit-tested across both regions and month boundaries | R35: Not started
A36: NB-035 | B36: E04 Localisation, RTL & i18n | C36: i18n | D36: Number, currency & numeral configuration | E36: Western digits by default for clinical and financial values; INR en-IN grouping vs SAR trailing symbol. Arabic-Indic tenant-configurable. | G36: Reception,Owner | H36: Shared | I36: Frontend | J36: Must | K36: MVP | L36: 3 | M36: 5 | N36: =IF(M36<=4,"R1 Foundation",IF(M36<=8,"R2 Core Clinic",IF(M36<=13,"R3 Revenue & Messaging",IF(M36<=18,"R4 Patient & Platform",IF(M36<=20,"R5 Harden","R6 Launch"))))) | O36: =L36*README!$B$32 | P36: NB-030 | Q36: Currency formatting matches the wireframe for both regions | R36: Not started
A37: NB-036 | B37: E04 Localisation, RTL & i18n | C37: i18n | D37: Ramadan & prayer-time schedule mode | E37: Prayer breaks and Ramadan hours change slot generation for KSA tenants. | F37: SYS-04,CAD-05 | G37: Reception,Doctor | H37: Clinic | I37: Fullstack | J37: Must | K37: MVP | L37: 5 | M37: 8 | N37: =IF(M37<=4,"R1 Foundation",IF(M37<=8,"R2 Core Clinic",IF(M37<=13,"R3 Revenue & Messaging",IF(M37<=18,"R4 Patient & Platform",IF(M37<=20,"R5 Harden","R6 Launch"))))) | O37: =L37*README!$B$32 | P37: NB-090 | Q37: Prayer blocks appear as non-bookable; Ramadan toggle shifts the whole day template | R37: Not started
A38: NB-037 | B38: E04 Localisation, RTL & i18n | C38: i18n | D38: String-expansion resilience pass | E38: ~30% expansion in Hindi and Arabic; every label container wraps, none truncate below two lines. | G38: All | H38: Shared | I38: Frontend | J38: Should | K38: MVP | L38: 3 | M38: 7 | N38: =IF(M38<=4,"R1 Foundation",IF(M38<=8,"R2 Core Clinic",IF(M38<=13,"R3 Revenue & Messaging",IF(M38<=18,"R4 Patient & Platform",IF(M38<=20,"R5 Harden","R6 Launch"))))) | O38: =L38*README!$B$32 | P38: NB-030 | Q38: Pseudo-locale run shows zero truncation defects | R38: Not started
A39: NB-038 | B39: E04 Localisation, RTL & i18n | C39: i18n | D39: Clinical & regulatory terminology review | E39: Native clinician review of Arabic and Hindi clinical strings. Mistranslation here is a patient-safety risk. | G39: Doctor,Nurse | H39: Shared | I39: QA | J39: Must | K39: MVP | L39: 5 | M39: 16 | N39: =IF(M39<=4,"R1 Foundation",IF(M39<=8,"R2 Core Clinic",IF(M39<=13,"R3 Revenue & Messaging",IF(M39<=18,"R4 Patient & Platform",IF(M39<=20,"R5 Harden","R6 Launch"))))) | O39: =L39*README!$B$32 | P39: NB-030, NB-103 | Q39: Sign-off from a licensed reviewer per language | R39: Not started
A40: NB-039 | B40: E04 Localisation, RTL & i18n | C40: i18n | D40: Voice-note handling on the patient channel | E40: Patients send voice notes; the clinic receives them transcribed or playable without leaving the inbox. | F40: PAT-15 | G40: Patient,Reception | H40: Patient | I40: Fullstack | J40: Should | K40: Phase 2 | L40: 8 | M40: 17 | N40: =IF(M40<=4,"R1 Foundation",IF(M40<=8,"R2 Core Clinic",IF(M40<=13,"R3 Revenue & Messaging",IF(M40<=18,"R4 Patient & Platform",IF(M40<=20,"R5 Harden","R6 Launch"))))) | O40: =L40*README!$B$32 | P40: NB-197, NB-030 | Q40: Voice note playable in the shared inbox; transcription failure degrades gracefully to audio | R40: Not started
...

Sheet Requirement Coverage
A1: Requirement coverage — every identifier found in the wireframe, and the tasks that deliver it
A2: Extracted programmatically from the wireframe source, not transcribed by hand. Uncovered rows turn red — there must be none.
A4: Requirement ID | B4: Area | C4: Description (from the wireframe) | D4: Work Starts In | E4: Tasks Delivering It | F4: Task Count | G4: Covered?
A5: AGG-01 | B5: Aggregator | C5: Nabd's shared number, invisible routing, verified-visit ratings | D5: MVP | E5: NB-221, NB-224, NB-288 | F5: 3 | G5: =IF(F5>0,"Yes","NO")
A6: AGG-02 | B6: Aggregator | C6: This may be an emergency. Call | D6: Phase 2 | E6: NB-222 | F6: 1 | G6: =IF(F6>0,"Yes","NO")
A7: AGG-03 | B7: Aggregator | D7: Phase 2 | E7: NB-223 | F7: 1 | G7: =IF(F7>0,"Yes","NO")
A8: AGG-04 | B8: Aggregator | C8: patient demand on the unified number vs actual coverage — the sales signal | D8: Phase 2 | E8: NB-227, NB-270 | F8: 2 | G8: =IF(F8>0,"Yes","NO")
A9: AGG-05 | B9: Aggregator | C9: A verified rating comes only from a completed, paid visit on the platform — fake reviews are impossible. Hidden until 10 ratings, showing \ | D9: Phase 2 | E9: NB-225, NB-226 | F9: 2 | G9: =IF(F9>0,"Yes","NO")
A10: AYU-02 | B10: Ayurveda | C10: Panchakarma | D10: Phase 2 | E10: NB-140 | F10: 1 | G10: =IF(F10>0,"Yes","NO")
A11: AYU-03 | B11: Ayurveda | C11: Herbal formulation (Ayurveda) | D11: Phase 2 | E11: NB-140 | F11: 1 | G11: =IF(F11>0,"Yes","NO")
A12: BIL-06 | B12: Billing | C12: Dues list | D12: MVP | E12: NB-171, NB-233 | F12: 2 | G12: =IF(F12>0,"Yes","NO")
A13: BIL-07 | B13: Billing | C13: Price transparency & estimates | D13: MVP | E13: NB-126, NB-170 | F13: 2 | G13: =IF(F13>0,"Yes","NO")
A14: BIL-11 | B14: Billing | C14: Insurance claim export | D14: MVP | E14: NB-070, NB-175 | F14: 2 | G14: =IF(F14>0,"Yes","NO")
A15: CAD-01 | B15: Setup | C15: Guided clinic setup wizard | D15: MVP | E15: NB-060, NB-069, NB-339 | F15: 3 | G15: =IF(F15>0,"Yes","NO")
A16: CAD-04 | B16: Setup | C16: CAD-04 · 24 charge heads | D16: MVP | E16: NB-061 | F16: 1 | G16: =IF(F16>0,"Yes","NO")
A17: CAD-05 | B17: Setup | C17: Schedule and calendar admin | D17: MVP | E17: NB-036, NB-064, NB-090, NB-091, NB-092 | F17: 5 | G17: =IF(F17>0,"Yes","NO")
A18: CAD-06 | B18: Setup | C18: Simple policy settings | D18: MVP | E18: NB-062 | F18: 1 | G18: =IF(F18>0,"Yes","NO")
A19: CAD-07 | B19: Setup | C19: WhatsApp number & template health | D19: MVP | E19: NB-069, NB-188, NB-189, NB-190, NB-239 | F19: 5 | G19: =IF(F19>0,"Yes","NO")
... A85: MKT-04 | B85: Marketing | C85: Influencer & social attribution | D85: MVP | E85: NB-079, NB-230 | F85: 2 | G85: =IF(F85>0,"Yes","NO")
A86: NFR-02 | B86: Non-func. | D86: MVP | E86: NB-006, NB-024, NB-029, NB-200, NB-273, NB-288, NB-316, NB-324, NB-327, NB-331 | F86: 10 | G86: =IF(F86>0,"Yes","NO")
A87: NFR-04 | B87: Non-func. | C87: no cross-region replication, region-scoped KMS keys | D87: MVP | E87: NB-001, NB-002, NB-254, NB-271, NB-283, NB-299, NB-306 | F87: 7 | G87: =IF(F87>0,"Yes","NO")
A88: NFR-06 | B88: Non-func. | D88: MVP | E88: NB-040, NB-042 | F88: 2 | G88: =IF(F88>0,"Yes","NO")
A89: NFR-07 | B89: Non-func. | C89: Regulator/owner export within 72h — NFR-07 · 3-year retention. | D89: MVP | E89: NB-078, NB-244, NB-247, NB-253 | F89: 4 | G89: =IF(F89>0,"Yes","NO")
A90: NFR-08 | B90: Non-func. | C90: Consent is checked at query level — NFR-08. | D90: MVP | E90: NB-053, NB-196, NB-241 | F90: 3 | G90: =IF(F90>0,"Yes","NO")
A91: NFR-09 | B91: Non-func. | C91: Annual CERT-In-empanelled VAPT (NFR-09) · annual drill with tenants. | D91: MVP | E91: NB-294, NB-295, NB-348 | F91: 3 | G91: =IF(F91>0,"Yes","NO")
A92: NFR-12 | B92: Non-func. | C92: A sync queue means a clinic working offline, not lost data. WhatsApp quality under 60% puts sending at risk. | D92: MVP | E92: NB-007, NB-020, NB-096, NB-263, NB-327, NB-328, NB-330, NB-341 | F92: 8 | G92: =IF(F92>0,"Yes","NO")
A93: NFR-18 | B93: Non-func. | C93: Fully self-serve, no support help needed — NFR-18. | D93: MVP | E93: NB-060, NB-068, NB-345 | F93: 3 | G93: =IF(F93>0,"Yes","NO")
A94: NUR-05 | B94: Nursing | C94: Clinical triage inbox | D94: MVP | E94: NB-144 | F94: 1 | G94: =IF(F94>0,"Yes","NO")
A95: ORTH-01 | B95: Ortho | C95: X-ray attach & review flag | D95: MVP | E95: NB-135 | F95: 1 | G95: =IF(F95>0,"Yes","NO")
A96: ORTH-02 | B96: Ortho | C96: Fracture/injury note templates | D96: MVP | E96: NB-135 | F96: 1 | G96: =IF(F96>0,"Yes","NO")
A97: ORTH-03 | B97: Ortho | C97: Physio session packages | D97: Phase 2 | E97: NB-136 | F97: 1 | G97: =IF(F97>0,"Yes","NO")
A98: OWN-01 | B98: Owner | C98: Daily money dashboard | D98: MVP | E98: NB-025, NB-229, NB-324, NB-332 | F98: 4 | G98: =IF(F98>0,"Yes","NO")
A99: OWN-02 | B99: Owner | C99: Where patients come from | D99: MVP | E99: NB-079, NB-230 | F99: 2 | G99: =IF(F99>0,"Yes","NO")
A100: OWN-03 | B100: Owner | C100: Repeat-patient & recall value | D100: Phase 2 | E100: NB-234 | F100: 1 | G100: =IF(F100>0,"Yes","NO")
... A189: SYS-25 | B189: Platform | C189: The clinic never touches Meta Business Manager — SYS-25 is a fully managed service. | D189: MVP | E189: NB-188 | F189: 1 | G189: =IF(F189>0,"Yes","NO")
A191: TOTAL | C191: ="Requirements in register: "&COUNTA(A5:A189) | F191: =SUM(F5:F189) | G191: =COUNTIF(G5:G189,"NO")&" uncovered"

Sheet Epics
A1: Epic rollup — every cell is a formula reading the Backlog tab
A3: Epic | B3: Tasks | C3: Story Points | D3: % of Total | E3: Est. Person-Days | F3: Must | G3: Should | H3: Could | I3: MVP | J3: Phase 2 | K3: Phase 3 | L3: First Sprint | M3: Last Sprint | N3: Done | O3: % Complete
A4: E01 Foundation & Architecture | B4: =COUNTIF(Backlog!$B$2:$B$352,$A4) | C4: =SUMIF(Backlog!$B$2:$B$352,$A4,Backlog!$L$2:$L$352) | D4: =IFERROR(C4/$C$33,0) | E4: =C4*README!$B$32 | F4: =COUNTIFS(Backlog!$B$2:$B$352,$A4,Backlog!$J$2:$J$352,"Must") | G4: =COUNTIFS(Backlog!$B$2:$B$352,$A4,Backlog!$J$2:$J$352,"Should") | H4: =COUNTIFS(Backlog!$B$2:$B$352,$A4,Backlog!$J$2:$J$352,"Could") | I4: =COUNTIFS(Backlog!$B$2:$B$352,$A4,Backlog!$K$2:$K$352,"MVP") | J4: =COUNTIFS(Backlog!$B$2:$B$352,$A4,Backlog!$K$2:$K$352,"Phase 2") | K4: =COUNTIFS(Backlog!$B$2:$B$352,$A4,Backlog!$K$2:$K$352,"Phase 3") | L4: =_xlfn.MINIFS(Backlog!$M$2:$M$352,Backlog!$B$2:$B$352,$A4) | M4: =_xlfn.MAXIFS(Backlog!$M$2:$M$352,Backlog!$B$2:$B$352,$A4) | N4: =COUNTIFS(Backlog!$B$2:$B$352,$A4,Backlog!$R$2:$R$352,"Done") | O4: =IFERROR(N4/B4,0)
A5: E02 Design System & UI Kit | B5: =COUNTIF(Backlog!$B$2:$B$352,$A5) | C5: =SUMIF(Backlog!$B$2:$B$352,$A5,Backlog!$L$2:$L$352) | D5: =IFERROR(C5/$C$33,0) | E5: =C5*README!$B$32 | F5: =COUNTIFS(Backlog!$B$2:$B$352,$A5,Backlog!$J$2:$J$352,"Must") | G5: =COUNTIFS(Backlog!$B$2:$B$352,$A5,Backlog!$J$2:$J$352,"Should") | H5: =COUNTIFS(Backlog!$B$2:$B$352,$A5,Backlog!$J$2:$J$352,"Could") | I5: =COUNTIFS(Backlog!$B$2:$B$352,$A5,Backlog!$K$2:$K$352,"MVP") | J5: =COUNTIFS(Backlog!$B$2:$B$352,$A5,Backlog!$K$2:$K$352,"Phase 2") | K5: =COUNTIFS(Backlog!$B$2:$B$352,$A5,Backlog!$K$2:$K$352,"Phase 3") | L5: =_xlfn.MINIFS(Backlog!$M$2:$M$352,Backlog!$B$2:$B$352,$A5) | M5: =_xlfn.MAXIFS(Backlog!$M$2:$M$352,Backlog!$B$2:$B$352,$A5) | N5: =COUNTIFS(Backlog!$B$2:$B$352,$A5,Backlog!$R$2:$R$352,"Done") | O5: =IFERROR(N5/B5,0)
A6: E03 Chart & Data-Visualisation System | B6: =COUNTIF(Backlog!$B$2:$B$352,$A6) | C6: =SUMIF(Backlog!$B$2:$B$352,$A6,Backlog!$L$2:$L$352) | D6: =IFERROR(C6/$C$33,0) | E6: =C6*README!$B$32 | F6: =COUNTIFS(Backlog!$B$2:$B$352,$A6,Backlog!$J$2:$J$352,"Must") | G6: =COUNTIFS(Backlog!$B$2:$B$352,$A6,Backlog!$J$2:$J$352,"Should") | H6: =COUNTIFS(Backlog!$B$2:$B$352,$A6,Backlog!$J$2:$J$352,"Could") | I6: =COUNTIFS(Backlog!$B$2:$B$352,$A6,Backlog!$K$2:$K$352,"MVP") | J6: =COUNTIFS(Backlog!$B$2:$B$352,$A6,Backlog!$K$2:$K$352,"Phase 2") | K6: =COUNTIFS(Backlog!$B$2:$B$352,$A6,Backlog!$K$2:$K$352,"Phase 3") | L6: =_xlfn.MINIFS(Backlog!$M$2:$M$352,Backlog!$B$2:$B$352,$A6) | M6: =_xlfn.MAXIFS(Backlog!$M$2:$M$352,Backlog!$B$2:$B$352,$A6) | N6: =COUNTIFS(Backlog!$B$2:$B$352,$A6,Backlog!$R$2:$R$352,"Done") | O6: =IFERROR(N6/B6,0)
A7: E04 Localisation, RTL & i18n | B7: =COUNTIF(Backlog!$B$2:$B$352,$A7) | C7: =SUMIF(Backlog!$B$2:$B$352,$A7,Backlog!$L$2:$L$352) | D7: =IFERROR(C7/$C$33,0) | E7: =C7*README!$B$32 | F7: =COUNTIFS(Backlog!$B$2:$B$352,$A7,Backlog!$J$2:$J$352,"Must") | G7: =COUNTIFS(Backlog!$B$2:$B$352,$A7,Backlog!$J$2:$J$352,"Should") | H7: =COUNTIFS(Backlog!$B$2:$B$352,$A7,Backlog!$J$2:$J$352,"Could") | I7: =COUNTIFS(Backlog!$B$2:$B$352,$A7,Backlog!$K$2:$K$352,"MVP") | J7: =COUNTIFS(Backlog!$B$2:$B$352,$A7,Backlog!$K$2:$K$352,"Phase 2") | K7: =COUNTIFS(Backlog!$B$2:$B$352,$A7,Backlog!$K$2:$K$352,"Phase 3") | L7: =_xlfn.MINIFS(Backlog!$M$2:$M$352,Backlog!$B$2:$B$352,$A7) | M7: =_xlfn.MAXIFS(Backlog!$M$2:$M$352,Backlog!$B$2:$B$352,$A7) | N7: =COUNTIFS(Backlog!$B$2:$B$352,$A7,Backlog!$R$2:$R$352,"Done") | O7: =IFERROR(N7/B7,0)
A8: E05 Identity, Auth & Session | B8: =COUNTIF(Backlog!$B$2:$B$352,$A8) | C8: =SUMIF(Backlog!$B$2:$B$352,$A8,Backlog!$L$2:$L$352) | D8: =IFERROR(C8/$C$33,0) | E8: =C8*README!$B$32 | F8: =COUNTIFS(Backlog!$B$2:$B$352,$A8,Backlog!$J$2:$J$352,"Must") | G8: =COUNTIFS(Backlog!$B$2:$B$352,$A8,Backlog!$J$2:$J$352,"Should") | H8: =COUNTIFS(Backlog!$B$2:$B$352,$A8,Backlog!$J$2:$J$352,"Could") | I8: =COUNTIFS(Backlog!$B$2:$B$352,$A8,Backlog!$K$2:$K$352,"MVP") | J8: =COUNTIFS(Backlog!$B$2:$B$352,$A8,Backlog!$K$2:$K$352,"Phase 2") | K8: =COUNTIFS(Backlog!$B$2:$B$352,$A8,Backlog!$K$2:$K$352,"Phase 3") | L8: =_xlfn.MINIFS(Backlog!$M$2:$M$352,Backlog!$B$2:$B$352,$A8) | M8: =_xlfn.MAXIFS(Backlog!$M$2:$M$352,Backlog!$B$2:$B$352,$A8) | N8: =COUNTIFS(Backlog!$B$2:$B$352,$A8,Backlog!$R$2:$R$352,"Done") | O8: =IFERROR(N8/B8,0)
A9: E06 RBAC & Permissions | B9: =COUNTIF(Backlog!$B$2:$B$352,$A9) | C9: =SUMIF(Backlog!$B$2:$B$352,$A9,Backlog!$L$2:$L$352) | D9: =IFERROR(C9/$C$33,0) | E9: =C9*README!$B$32 | F9: =COUNTIFS(Backlog!$B$2:$B$352,$A9,Backlog!$J$2:$J$352,"Must") | G9: =COUNTIFS(Backlog!$B$2:$B$352,$A9,Backlog!$J$2:$J$352,"Should") | H9: =COUNTIFS(Backlog!$B$2:$B$352,$A9,Backlog!$J$2:$J$352,"Could") | I9: =COUNTIFS(Backlog!$B$2:$B$352,$A9,Backlog!$K$2:$K$352,"MVP") | J9: =COUNTIFS(Backlog!$B$2:$B$352,$A9,Backlog!$K$2:$K$352,"Phase 2") | K9: =COUNTIFS(Backlog!$B$2:$B$352,$A9,Backlog!$K$2:$K$352,"Phase 3") | L9: =_xlfn.MINIFS(Backlog!$M$2:$M$352,Backlog!$B$2:$B$352,$A9) | M9: =_xlfn.MAXIFS(Backlog!$M$2:$M$352,Backlog!$B$2:$B$352,$A9) | N9: =COUNTIFS(Backlog!$B$2:$B$352,$A9,Backlog!$R$2:$R$352,"Done") | O9: =IFERROR(N9/B9,0)
A10: E07 Clinic Setup & Administration | B10: =COUNTIF(Backlog!$B$2:$B$352,$A10) | C10: =SUMIF(Backlog!$B$2:$B$352,$A10,Backlog!$L$2:$L$352) | D10: =IFERROR(C10/$C$33,0) | E10: =C10*README!$B$32 | F10: =COUNTIFS(Backlog!$B$2:$B$352,$A10,Backlog!$J$2:$J$352,"Must") | G10: =COUNTIFS(Backlog!$B$2:$B$352,$A10,Backlog!$J$2:$J$352,"Should") | H10: =COUNTIFS(Backlog!$B$2:$B$352,$A10,Backlog!$J$2:$J$352,"Could") | I10: =COUNTIFS(Backlog!$B$2:$B$352,$A10,Backlog!$K$2:$K$352,"MVP") | J10: =COUNTIFS(Backlog!$B$2:$B$352,$A10,Backlog!$K$2:$K$352,"Phase 2") | K10: =COUNTIFS(Backlog!$B$2:$B$352,$A10,Backlog!$K$2:$K$352,"Phase 3") | L10: =_xlfn.MINIFS(Backlog!$M$2:$M$352,Backlog!$B$2:$B$352,$A10) | M10: =_xlfn.MAXIFS(Backlog!$M$2:$M$352,Backlog!$B$2:$B$352,$A10) | N10: =COUNTIFS(Backlog!$B$2:$B$352,$A10,Backlog!$R$2:$R$352,"Done") | O10: =IFERROR(N10/B10,0)
A11: E08 Patient Records & Registration | B11: =COUNTIF(Backlog!$B$2:$B$352,$A11) | C11: =SUMIF(Backlog!$B$2:$B$352,$A11,Backlog!$L$2:$L$352) | D11: =IFERROR(C11/$C$33,0) | E11: =C11*README!$B$32 | F11: =COUNTIFS(Backlog!$B$2:$B$352,$A11,Backlog!$J$2:$J$352,"Must") | G11: =COUNTIFS(Backlog!$B$2:$B$352,$A11,Backlog!$J$2:$J$352,"Should") | H11: =COUNTIFS(Backlog!$B$2:$B$352,$A11,Backlog!$J$2:$J$352,"Could") | I11: =COUNTIFS(Backlog!$B$2:$B$352,$A11,Backlog!$K$2:$K$352,"MVP") | J11: =COUNTIFS(Backlog!$B$2:$B$352,$A11,Backlog!$K$2:$K$352,"Phase 2") | K11: =COUNTIFS(Backlog!$B$2:$B$352,$A11,Backlog!$K$2:$K$352,"Phase 3") | L11: =_xlfn.MINIFS(Backlog!$M$2:$M$352,Backlog!$B$2:$B$352,$A11) | M11: =_xlfn.MAXIFS(Backlog!$M$2:$M$352,Backlog!$B$2:$B$352,$A11) | N11: =COUNTIFS(Backlog!$B$2:$B$352,$A11,Backlog!$R$2:$R$352,"Done") | O11: =IFERROR(N11/B11,0)
A12: E09 Caregiver, Family & Guardianship | B12: =COUNTIF(Backlog!$B$2:$B$352,$A12) | C12: =SUMIF(Backlog!$B$2:$B$352,$A12,Backlog!$L$2:$L$352) | D12: =IFERROR(C12/$C$33,0) | E12: =C12*README!$B$32 | F12: =COUNTIFS(Backlog!$B$2:$B$352,$A12,Backlog!$J$2:$J$352,"Must") | G12: =COUNTIFS(Backlog!$B$2:$B$352,$A12,Backlog!$J$2:$J$352,"Should") | H12: =COUNTIFS(Backlog!$B$2:$B$352,$A12,Backlog!$J$2:$J$352,"Could") | I12: =COUNTIFS(Backlog!$B$2:$B$352,$A12,Backlog!$K$2:$K$352,"MVP") | J12: =COUNTIFS(Backlog!$B$2:$B$352,$A12,Backlog!$K$2:$K$352,"Phase 2") | K12: =COUNTIFS(Backlog!$B$2:$B$352,$A12,Backlog!$K$2:$K$352,"Phase 3") | L12: =_xlfn.MINIFS(Backlog!$M$2:$M$352,Backlog!$B$2:$B$352,$A12) | M12: =_xlfn.MAXIFS(Backlog!$M$2:$M$352,Backlog!$B$2:$B$352,$A12) | N12: =COUNTIFS(Backlog!$B$2:$B$352,$A12,Backlog!$R$2:$R$352,"Done") | O12: =IFERROR(N12/B12,0)
A13: E10 Queue, Scheduling & Availability | B13: =COUNTIF(Backlog!$B$2:$B$352,$A13) | C13: =SUMIF(Backlog!$B$2:$B$352,$A13,Backlog!$L$2:$L$352) | D13: =IFERROR(C13/$C$33,0) | E13: =C13*README!$B$32 | F13: =COUNTIFS(Backlog!$B$2:$B$352,$A13,Backlog!$J$2:$J$352,"Must") | G13: =COUNTIFS(Backlog!$B$2:$B$352,$A13,Backlog!$J$2:$J$352,"Should") | H13: =COUNTIFS(Backlog!$B$2:$B$352,$A13,Backlog!$J$2:$J$352,"Could") | I13: =COUNTIFS(Backlog!$B$2:$B$352,$A13,Backlog!$K$2:$K$352,"MVP") | J13: =COUNTIFS(Backlog!$B$2:$B$352,$A13,Backlog!$K$2:$K$352,"Phase 2") | K13: =COUNTIFS(Backlog!$B$2:$B$352,$A13,Backlog!$K$2:$K$352,"Phase 3") | L13: =_xlfn.MINIFS(Backlog!$M$2:$M$352,Backlog!$B$2:$B$352,$A13) | M13: =_xlfn.MAXIFS(Backlog!$M$2:$M$352,Backlog!$B$2:$B$352,$A13) | N13: =COUNTIFS(Backlog!$B$2:$B$352,$A13,Backlog!$R$2:$R$352,"Done") | O13: =IFERROR(N13/B13,0)
A14: E11 Clinical Workspace | B14: =COUNTIF(Backlog!$B$2:$B$352,$A14) | C14: =SUMIF(Backlog!$B$2:$B$352,$A14,Backlog!$L$2:$L$352) | D14: =IFERROR(C14/$C$33,0) | E14: =C14*README!$B$32 | F14: =COUNTIFS(Backlog!$B$2:$B$352,$A14,Backlog!$J$2:$J$352,"Must") | G14: =COUNTIFS(Backlog!$B$2:$B$352,$A14,Backlog!$J$2:$J$352,"Should") | H14: =COUNTIFS(Backlog!$B$2:$B$352,$A14,Backlog!$J$2:$J$352,"Could") | I14: =COUNTIFS(Backlog!$B$2:$B$352,$A14,Backlog!$K$2:$K$352,"MVP") | J14: =COUNTIFS(Backlog!$B$2:$B$352,$A14,Backlog!$K$2:$K$352,"Phase 2") | K14: =COUNTIFS(Backlog!$B$2:$B$352,$A14,Backlog!$K$2:$K$352,"Phase 3") | L14: =_xlfn.MINIFS(Backlog!$M$2:$M$352,Backlog!$B$2:$B$352,$A14) | M14: =_xlfn.MAXIFS(Backlog!$M$2:$M$352,Backlog!$B$2:$B$352,$A14) | N14: =COUNTIFS(Backlog!$B$2:$B$352,$A14,Backlog!$R$2:$R$352,"Done") | O14: =IFERROR(N14/B14,0)
A15: E12 Specialty Workspaces | B15: =COUNTIF(Backlog!$B$2:$B$352,$A15) | C15: =SUMIF(Backlog!$B$2:$B$352,$A15,Backlog!$L$2:$L$352) | D15: =IFERROR(C15/$C$33,0) | E15: =C15*README!$B$32 | F15: =COUNTIFS(Backlog!$B$2:$B$352,$A15,Backlog!$J$2:$J$352,"Must") | G15: =COUNTIFS(Backlog!$B$2:$B$352,$A15,Backlog!$J$2:$J$352,"Should") | H15: =COUNTIFS(Backlog!$B$2:$B$352,$A15,Backlog!$J$2:$J$352,"Could") | I15: =COUNTIFS(Backlog!$B$2:$B$352,$A15,Backlog!$K$2:$K$352,"MVP") | J15: =COUNTIFS(Backlog!$B$2:$B$352,$A15,Backlog!$K$2:$K$352,"Phase 2") | K15: =COUNTIFS(Backlog!$B$2:$B$352,$A15,Backlog!$K$2:$K$352,"Phase 3") | L15: =_xlfn.MINIFS(Backlog!$M$2:$M$352,Backlog!$B$2:$B$352,$A15) | M15: =_xlfn.MAXIFS(Backlog!$M$2:$M$352,Backlog!$B$2:$B$352,$A15) | N15: =COUNTIFS(Backlog!$B$2:$B$352,$A15,Backlog!$R$2:$R$352,"Done") | O15: =IFERROR(N15/B15,0)
... A32: E29 Launch, Migration & Handover | B32: =COUNTIF(Backlog!$B$2:$B$352,$A32) | C32: =SUMIF(Backlog!$B$2:$B$352,$A32,Backlog!$L$2:$L$352) | D32: =IFERROR(C32/$C$33,0) | E32: =C32*README!$B$32 | F32: =COUNTIFS(Backlog!$B$2:$B$352,$A32,Backlog!$J$2:$J$352,"Must") | G32: =COUNTIFS(Backlog!$B$2:$B$352,$A32,Backlog!$J$2:$J$352,"Should") | H32: =COUNTIFS(Backlog!$B$2:$B$352,$A32,Backlog!$J$2:$J$352,"Could") | I32: =COUNTIFS(Backlog!$B$2:$B$352,$A32,Backlog!$K$2:$K$352,"MVP") | J32: =COUNTIFS(Backlog!$B$2:$B$352,$A32,Backlog!$K$2:$K$352,"Phase 2") | K32: =COUNTIFS(Backlog!$B$2:$B$352,$A32,Backlog!$K$2:$K$352,"Phase 3") | L32: =_xlfn.MINIFS(Backlog!$M$2:$M$352,Backlog!$B$2:$B$352,$A32) | M32: =_xlfn.MAXIFS(Backlog!$M$2:$M$352,Backlog!$B$2:$B$352,$A32) | N32: =COUNTIFS(Backlog!$B$2:$B$352,$A32,Backlog!$R$2:$R$352,"Done") | O32: =IFERROR(N32/B32,0)
A33: TOTAL | B33: =SUM(B4:B32) | C33: =SUM(C4:C32) | D33: =SUM(D4:D32) | E33: =SUM(E4:E32) | F33: =SUM(F4:F32) | G33: =SUM(G4:G32) | H33: =SUM(H4:H32) | I33: =SUM(I4:I32) | ... K33: =SUM(K4:K32) | L33: =MIN(L4:L32) | M33: =MAX(M4:M32) | N33: =SUM(N4:N32) | O33: =IFERROR(N33/B33,0)

Sheet Sprints
A1: Sprint load against ramped squad capacity
A2: Capacity = squads that sprint x README!B31. Squad counts are blue input cells — change them and every capacity figure moves.
A4: Sprint | B4: Release Band | C4: Squads | D4: Capacity | E4: Tasks | F4: Story Points | G4: Head-room | H4: Utilisation | I4: Est. Person-Days | J4: Must Tasks | K4: Cumulative Points | L4: % of Programme
A5: 1 | B5: =IF(A5<=4,"R1 Foundation",IF(A5<=8,"R2 Core Clinic",IF(A5<=13,"R3 Revenue & Messaging",IF(A5<=18,"R4 Patient & Platform",IF(A5<=20,"R5 Harden","R6 Launch"))))) | C5: 2 | D5: =C5*README!$B$31 | E5: =COUNTIF(Backlog!$M$2:$M$352,$A5) | F5: =SUMIF(Backlog!$M$2:$M$352,$A5,Backlog!$L$2:$L$352) | G5: =D5-F5 | H5: =IFERROR(F5/D5,0) | I5: =F5*README!$B$32 | J5: =COUNTIFS(Backlog!$M$2:$M$352,$A5,Backlog!$J$2:$J$352,"Must") | K5: =SUM($F$5:F5) | L5: =IFERROR(K5/SUM($F$5:$F$27),0)
A6: 2 | B6: =IF(A6<=4,"R1 Foundation",IF(A6<=8,"R2 Core Clinic",IF(A6<=13,"R3 Revenue & Messaging",IF(A6<=18,"R4 Patient & Platform",IF(A6<=20,"R5 Harden","R6 Launch"))))) | C6: 2 | D6: =C6*README!$B$31 | E6: =COUNTIF(Backlog!$M$2:$M$352,$A6) | F6: =SUMIF(Backlog!$M$2:$M$352,$A6,Backlog!$L$2:$L$352) | G6: =D6-F6 | H6: =IFERROR(F6/D6,0) | I6: =F6*README!$B$32 | J6: =COUNTIFS(Backlog!$M$2:$M$352,$A6,Backlog!$J$2:$J$352,"Must") | K6: =SUM($F$5:F6) | L6: =IFERROR(K6/SUM($F$5:$F$27),0)
A7: 3 | B7: =IF(A7<=4,"R1 Foundation",IF(A7<=8,"R2 Core Clinic",IF(A7<=13,"R3 Revenue & Messaging",IF(A7<=18,"R4 Patient & Platform",IF(A7<=20,"R5 Harden","R6 Launch"))))) | C7: 2 | D7: =C7*README!$B$31 | E7: =COUNTIF(Backlog!$M$2:$M$352,$A7) | F7: =SUMIF(Backlog!$M$2:$M$352,$A7,Backlog!$L$2:$L$352) | G7: =D7-F7 | H7: =IFERROR(F7/D7,0) | I7: =F7*README!$B$32 | J7: =COUNTIFS(Backlog!$M$2:$M$352,$A7,Backlog!$J$2:$J$352,"Must") | K7: =SUM($F$5:F7) | L7: =IFERROR(K7/SUM($F$5:$F$27),0)
A8: 4 | B8: =IF(A8<=4,"R1 Foundation",IF(A8<=8,"R2 Core Clinic",IF(A8<=13,"R3 Revenue & Messaging",IF(A8<=18,"R4 Patient & Platform",IF(A8<=20,"R5 Harden","R6 Launch"))))) | C8: 2 | D8: =C8*README!$B$31 | E8: =COUNTIF(Backlog!$M$2:$M$352,$A8) | F8: =SUMIF(Backlog!$M$2:$M$352,$A8,Backlog!$L$2:$L$352) | G8: =D8-F8 | H8: =IFERROR(F8/D8,0) | I8: =F8*README!$B$32 | J8: =COUNTIFS(Backlog!$M$2:$M$352,$A8,Backlog!$J$2:$J$352,"Must") | K8: =SUM($F$5:F8) | L8: =IFERROR(K8/SUM($F$5:$F$27),0)
A9: 5 | B9: =IF(A9<=4,"R1 Foundation",IF(A9<=8,"R2 Core Clinic",IF(A9<=13,"R3 Revenue & Messaging",IF(A9<=18,"R4 Patient & Platform",IF(A9<=20,"R5 Harden","R6 Launch"))))) | C9: 2 | D9: =C9*README!$B$31 | E9: =COUNTIF(Backlog!$M$2:$M$352,$A9) | F9: =SUMIF(Backlog!$M$2:$M$352,$A9,Backlog!$L$2:$L$352) | G9: =D9-F9 | H9: =IFERROR(F9/D9,0) | I9: =F9*README!$B$32 | J9: =COUNTIFS(Backlog!$M$2:$M$352,$A9,Backlog!$J$2:$J$352,"Must") | K9: =SUM($F$5:F9) | L9: =IFERROR(K9/SUM($F$5:$F$27),0)
A10: 6 | B10: =IF(A10<=4,"R1 Foundation",IF(A10<=8,"R2 Core Clinic",IF(A10<=13,"R3 Revenue & Messaging",IF(A10<=18,"R4 Patient & Platform",IF(A10<=20,"R5 Harden","R6 Launch"))))) | C10: 2 | D10: =C10*README!$B$31 | E10: =COUNTIF(Backlog!$M$2:$M$352,$A10) | F10: =SUMIF(Backlog!$M$2:$M$352,$A10,Backlog!$L$2:$L$352) | G10: =D10-F10 | H10: =IFERROR(F10/D10,0) | I10: =F10*README!$B$32 | J10: =COUNTIFS(Backlog!$M$2:$M$352,$A10,Backlog!$J$2:$J$352,"Must") | K10: =SUM($F$5:F10) | L10: =IFERROR(K10/SUM($F$5:$F$27),0)
A11: 7 | B11: =IF(A11<=4,"R1 Foundation",IF(A11<=8,"R2 Core Clinic",IF(A11<=13,"R3 Revenue & Messaging",IF(A11<=18,"R4 Patient & Platform",IF(A11<=20,"R5 Harden","R6 Launch"))))) | C11: 3 | D11: =C11*README!$B$31 | E11: =COUNTIF(Backlog!$M$2:$M$352,$A11) | F11: =SUMIF(Backlog!$M$2:$M$352,$A11,Backlog!$L$2:$L$352) | G11: =D11-F11 | H11: =IFERROR(F11/D11,0) | I11: =F11*README!$B$32 | J11: =COUNTIFS(Backlog!$M$2:$M$352,$A11,Backlog!$J$2:$J$352,"Must") | K11: =SUM($F$5:F11) | L11: =IFERROR(K11/SUM($F$5:$F$27),0)
A12: 8 | B12: =IF(A12<=4,"R1 Foundation",IF(A12<=8,"R2 Core Clinic",IF(A12<=13,"R3 Revenue & Messaging",IF(A12<=18,"R4 Patient & Platform",IF(A12<=20,"R5 Harden","R6 Launch"))))) | C12: 2 | D12: =C12*README!$B$31 | E12: =COUNTIF(Backlog!$M$2:$M$352,$A12) | F12: =SUMIF(Backlog!$M$2:$M$352,$A12,Backlog!$L$2:$L$352) | G12: =D12-F12 | H12: =IFERROR(F12/D12,0) | I12: =F12*README!$B$32 | J12: =COUNTIFS(Backlog!$M$2:$M$352,$A12,Backlog!$J$2:$J$352,"Must") | K12: =SUM($F$5:F12) | L12: =IFERROR(K12/SUM($F$5:$F$27),0)
A13: 9 | B13: =IF(A13<=4,"R1 Foundation",IF(A13<=8,"R2 Core Clinic",IF(A13<=13,"R3 Revenue & Messaging",IF(A13<=18,"R4 Patient & Platform",IF(A13<=20,"R5 Harden","R6 Launch"))))) | C13: 3 | D13: =C13*README!$B$31 | E13: =COUNTIF(Backlog!$M$2:$M$352,$A13) | F13: =SUMIF(Backlog!$M$2:$M$352,$A13,Backlog!$L$2:$L$352) | G13: =D13-F13 | H13: =IFERROR(F13/D13,0) | I13: =F13*README!$B$32 | J13: =COUNTIFS(Backlog!$M$2:$M$352,$A13,Backlog!$J$2:$J$352,"Must") | K13: =SUM($F$5:F13) | L13: =IFERROR(K13/SUM($F$5:$F$27),0)
A14: 10 | B14: =IF(A14<=4,"R1 Foundation",IF(A14<=8,"R2 Core Clinic",IF(A14<=13,"R3 Revenue & Messaging",IF(A14<=18,"R4 Patient & Platform",IF(A14<=20,"R5 Harden","R6 Launch"))))) | C14: 3 | D14: =C14*README!$B$31 | E14: =COUNTIF(Backlog!$M$2:$M$352,$A14) | F14: =SUMIF(Backlog!$M$2:$M$352,$A14,Backlog!$L$2:$L$352) | G14: =D14-F14 | H14: =IFERROR(F14/D14,0) | I14: =F14*README!$B$32 | J14: =COUNTIFS(Backlog!$M$2:$M$352,$A14,Backlog!$J$2:$J$352,"Must") | K14: =SUM($F$5:F14) | L14: =IFERROR(K14/SUM($F$5:$F$27),0)
A15: 11 | B15: =IF(A15<=4,"R1 Foundation",IF(A15<=8,"R2 Core Clinic",IF(A15<=13,"R3 Revenue & Messaging",IF(A15<=18,"R4 Patient & Platform",IF(A15<=20,"R5 Harden","R6 Launch"))))) | C15: 3 | D15: =C15*README!$B$31 | E15: =COUNTIF(Backlog!$M$2:$M$352,$A15) | F15: =SUMIF(Backlog!$M$2:$M$352,$A15,Backlog!$L$2:$L$352) | G15: =D15-F15 | H15: =IFERROR(F15/D15,0) | I15: =F15*README!$B$32 | J15: =COUNTIFS(Backlog!$M$2:$M$352,$A15,Backlog!$J$2:$J$352,"Must") | K15: =SUM($F$5:F15) | L15: =IFERROR(K15/SUM($F$5:$F$27),0)
A16: 12 | B16: =IF(A16<=4,"R1 Foundation",IF(A16<=8,"R2 Core Clinic",IF(A16<=13,"R3 Revenue & Messaging",IF(A16<=18,"R4 Patient & Platform",IF(A16<=20,"R5 Harden","R6 Launch"))))) | C16: 4 | D16: =C16*README!$B$31 | E16: =COUNTIF(Backlog!$M$2:$M$352,$A16) | F16: =SUMIF(Backlog!$M$2:$M$352,$A16,Backlog!$L$2:$L$352) | G16: =D16-F16 | H16: =IFERROR(F16/D16,0) | I16: =F16*README!$B$32 | J16: =COUNTIFS(Backlog!$M$2:$M$352,$A16,Backlog!$J$2:$J$352,"Must") | K16: =SUM($F$5:F16) | L16: =IFERROR(K16/SUM($F$5:$F$27),0)
... A27: 23 | B27: =IF(A27<=4,"R1 Foundation",IF(A27<=8,"R2 Core Clinic",IF(A27<=13,"R3 Revenue & Messaging",IF(A27<=18,"R4 Patient & Platform",IF(A27<=20,"R5 Harden","R6 Launch"))))) | C27: 2 | D27: =C27*README!$B$31 | E27: =COUNTIF(Backlog!$M$2:$M$352,$A27) | F27: =SUMIF(Backlog!$M$2:$M$352,$A27,Backlog!$L$2:$L$352) | G27: =D27-F27 | H27: =IFERROR(F27/D27,0) | I27: =F27*README!$B$32 | J27: =COUNTIFS(Backlog!$M$2:$M$352,$A27,Backlog!$J$2:$J$352,"Must") | K27: =SUM($F$5:F27) | L27: =IFERROR(K27/SUM($F$5:$F$27),0)
A28: TOTAL | D28: =SUM(D5:D27) | E28: =SUM(E5:E27) | F28: =SUM(F5:F27) | H28: =IFERROR(F28/D28,0) | I28: =SUM(I5:I27) | J28: =SUM(J5:J27)
A30: Programme shape
A31: Elapsed weeks | D31: =README!$B$30*23
A32: Approximate elapsed months | D32: =D31/4.345
A33: Peak squads in parallel | D33: =MAX(C5:C27)
A34: Peak people (approx, 6 per squad) | D34: =D33*6
A35: Indicative cost (only if a day rate is set on README) | D35: =I28*README!$B$33

Sheet Tracks
A1: Parallel delivery tracks
A2: This programme cannot be delivered by one team. These are the four workstreams the backlog naturally separates into.
A4: Track | B4: What it covers | C4: Tasks | D4: Story Points | E4: % of Points | F4: Est. Person-Days | G4: First Sprint | H4: Last Sprint
A5: Shared | B5: Foundation, design system, charts, i18n, auth, security, DevOps and QA — everything the other three depend on | C5: =COUNTIF(Backlog!$H$2:$H$352,$A5) | D5: =SUMIF(Backlog!$H$2:$H$352,$A5,Backlog!$L$2:$L$352) | E5: =IFERROR(D5/$D$9,0) | F5: =D5*README!$B$32 | G5: =_xlfn.MINIFS(Backlog!$M$2:$M$352,Backlog!$H$2:$H$352,$A5) | H5: =_xlfn.MAXIFS(Backlog!$M$2:$M$352,Backlog!$H$2:$H$352,$A5)
A6: Clinic | B6: Reception, doctor, nurse and owner surfaces: queue, clinical, billing, packages, pharmacy, reports | C6: =COUNTIF(Backlog!$H$2:$H$352,$A6) | D6: =SUMIF(Backlog!$H$2:$H$352,$A6,Backlog!$L$2:$L$352) | E6: =IFERROR(D6/$D$9,0) | F6: =D6*README!$B$32 | G6: =_xlfn.MINIFS(Backlog!$M$2:$M$352,Backlog!$H$2:$H$352,$A6) | H6: =_xlfn.MAXIFS(Backlog!$M$2:$M$352,Backlog!$H$2:$H$352,$A6)
A7: Patient | B7: The WhatsApp patient surface, caregiver and family handling, messaging infrastructure and the aggregator | C7: =COUNTIF(Backlog!$H$2:$H$352,$A7) | D7: =SUMIF(Backlog!$H$2:$H$352,$A7,Backlog!$L$2:$L$352) | E7: =IFERROR(D7/$D$9,0) | F7: =D7*README!$B$32 | G7: =_xlfn.MINIFS(Backlog!$M$2:$M$352,Backlog!$H$2:$H$352,$A7) | H7: =_xlfn.MAXIFS(Backlog!$M$2:$M$352,Backlog!$H$2:$H$352,$A7)
A8: Platform | B8: The SaaS console: provisioning, operator roles, subscriptions, support, health, territories and growth | C8: =COUNTIF(Backlog!$H$2:$H$352,$A8) | D8: =SUMIF(Backlog!$H$2:$H$352,$A8,Backlog!$L$2:$L$352) | E8: =IFERROR(D8/$D$9,0) | F8: =D8*README!$B$32 | G8: =_xlfn.MINIFS(Backlog!$M$2:$M$352,Backlog!$H$2:$H$352,$A8) | H8: =_xlfn.MAXIFS(Backlog!$M$2:$M$352,Backlog!$H$2:$H$352,$A8)
A9: TOTAL | C9: =SUM(C5:C8) | D9: =SUM(D5:D8) | E9: =SUM(E5:E8) | F9: =SUM(F5:F8)

Sheet RBAC Matrix
A1: Clinic role & permission matrix — specification for epic E06
A2: Taken from the wireframe permission model. Y granted, N not granted, P plan/subscription dependent, - not applicable.
A3: Rule: a permission-restricted element is ABSENT, never disabled or greyed. Enforcement is server-side; the UI only reflects it. Consent is additionally checked at query level (NFR-08).
A5: Role | B5: Module | C5: View | D5: Create | E5: Edit | F5: Delete / Void | G5: Approve | H5: Refund / Discount | I5: Export | J5: Notes
A6: Owner / Manager | B6: Patients | C6: Y | D6: Y | E6: Y | F6: Y | G6: Y | H6: - | I6: Y
B7: Queue & Appointments | C7: Y | D7: Y | E7: Y | F7: Y | G7: Y | H7: - | I7: Y
B8: Clinical Records | C8: Y | D8: N | E8: N | F8: Y | G8: Y | H8: - | I8: Y
B9: Billing & Payments | C9: Y | D9: Y | E9: Y | F9: Y | G9: Y | H9: Y | I9: Y
B10: Packages | C10: Y | D10: Y | E10: Y | F10: Y | G10: Y | H10: Y | I10: Y
B11: Pharmacy | C11: P | D11: P | E11: P | F11: P | G11: P | H11: P | I11: P | J11: Pharmacy availability follows the tenant plan and pharmacy mode (CAD-11), not the role.
B12: Reports | C12: Y | D12: - | E12: - | F12: - | G12: Y | H12: - | I12: Y
B13: Staff & Access | C13: Y | D13: Y | E13: Y | F13: Y | G13: Y | H13: - | I13: Y
B14: Clinic Setup | C14: Y | D14: - | E14: Y | F14: - | G14: - | H14: - | I14: Y
B15: Compliance & Audit | C15: Y | D15: - | E15: - | F15: Y | G15: Y | H15: - | I15: Y
A16: Doctor | B16: Patients | C16: Y | D16: Y | E16: Y | F16: - | G16: N | H16: - | I16: - | J16: Scope is per staff member: own patients only, or all clinic patients. Enforced in the query (E06).
B17: Queue & Appointments | C17: Y | D17: - | E17: Y | F17: - | G17: - | H17: - | I17: -
B18: Clinical Records | C18: Y | D18: Y | E18: Y | F18: Y | G18: N | H18: - | I18: -
B19: Billing & Payments | C19: Y | D19: - | E19: - | F19: - | G19: - | H19: - | I19: -
B20: Packages | C20: Y | D20: Y | E20: Y | F20: - | G20: - | H20: - | I20: -
B21: Pharmacy | C21: P | D21: P | E21: N | F21: - | G21: - | H21: - | I21: - | J21: External mode removes dispensing entirely; hybrid and in-house are paid tiers.
B22: Reports | C22: Y | D22: - | E22: - | F22: - | G22: N | H22: - | I22: -
B23: Staff & Access | C23: N | D23: - | E23: - | F23: - | G23: - | H23: - | I23: -
B24: Clinic Setup | C24: N | D24: - | E24: - | F24: - | G24: - | H24: - | I24: -
B25: Compliance & Audit | C25: N | D25: - | E25: - | F25: - | G25: - | H25: - | I25: -
A26: Receptionist | B26: Patients | C26: Y | D26: Y | E26: Y | F26: - | G26: N | H26: - | I26: -
B27: Queue & Appointments | C27: Y | D27: Y | E27: Y | F27: - | G27: - | H27: - | I27: -
B28: Clinical Records | C28: N | D28: - | E28: - | F28: - | G28: - | H28: - | I28: -
B29: Billing & Payments | C29: Y | D29: Y | E29: Y | F29: N | G29: Y | H29: N | I29: - | J29: Refund and discount rights are individually revocable — the wireframe shows a 'no refund, no discount' receptionist.
B30: Packages | C30: Y | D30: Y | E30: N | F30: - | G30: - | H30: - | I30: -
B31: Pharmacy | C31: P | D31: P | E31: N | F31: - | G31: - | H31: - | I31: -
B32: Reports | C32: N | D32: - | E32: - | F32: - | G32: - | H32: - | I32: -
B33: Staff & Access | C33: N | D33: - | E33: - | F33: - | G33: - | H33: - | I33: -
B34: Clinic Setup | C34: N | D34: - | E34: - | F34: - | G34: - | H34: - | I34: -
B35: Compliance & Audit | C35: N | D35: - | E35: - | F35: - | G35: - | H35: - | I35: -
A36: Nurse | B36: Patients | C36: Y | D36: N | E36: Y | F36: - | G36: N | H36: - | I36: -
B37: Queue & Appointments | C37: Y | D37: - | E37: Y | F37: - | G37: - | H37: - | I37: -
B38: Clinical Records | C38: Y | D38: Y | E38: Y | F38: - | G38: N | H38: - | I38: - | J38: May be narrowed to vitals and vaccines only.
B39: Billing & Payments | C39: N | D39: - | E39: - | F39: - | G39: - | H39: - | I39: -
B40: Packages | C40: Y | D40: - | E40: Y | F40: - | G40: - | H40: - | I40: -
B41: Pharmacy | C41: P | D41: N | E41: N | F41: - | G41: - | H41: - | I41: -
...

Sheet SaaS Operator Roles
A1: Platform-side operator roles (SSA-02) — specification for epic E22
A2: Seven roles. No single super-admin does everything. A role without create rights has no create button anywhere — the element is absent, not disabled.
A4: Surface | B4: Super admin | C4: Implementation | D4: Support engineer | E4: Billing | F4: SRE | G4: Commercial (read-only) | H4: Compliance / DPO
A5: Command Centre | B5: Y | C5: Y | D5: Y | E5: Y | F5: Y | G5: Y | H5: Y
A6: Clinics / fleet | B6: Y | C6: Y | D6: Y | E6: Y | F6: — | G6: Y | H6: Y
A7: Tenant detail | B7: Y | C7: Y | D7: Y | E7: — | F7: — | G7: — | H7: Y
A8: Onboarding / provisioning | B8: Y | C8: Y | D8: — | E8: — | F8: — | G8: — | H8: —
A9: Provisioning jobs | B9: Y | C9: Y | D9: — | E9: — | F9: Y | G9: — | H9: —
A10: Billing & revenue | B10: Y | C10: — | D10: — | E10: Y | F10: — | G10: Y | H10: —
